<?xml version="1.0" ?>
<!-- =================================================================================== -->
<!-- |    This document was autogenerated by xacro from cassie_simple.xacro            | -->
<!-- |    EDITING THIS FILE BY HAND IS NOT RECOMMENDED                                 | -->
<!-- =================================================================================== -->
<!-- Author: Xiaobin Xiong
     Date:   5/02/2022   -->
<robot name="cassie_model" xmlns:xacro="http://ros.org/wiki/xacro">
  <link name="BaseRotZLink">
    <inertial>
      <origin xyz="0.0507 0.0 0.0284"/>
      <mass value="10.33"/>
      <inertia ixx="0.0942" ixy="0.000169" ixz="0.015" iyy="0.084" iyz="0.000516" izz="0.113"/>
    </inertial>
    <visual>
      <geometry>
        <mesh filename="package://cassie_model/meshes/BaseRotZ.stl"/>
      </geometry>
      <material name="">
        <color rgba="1.0 0.43137254902 0.117647058824 1"/>
      </material>
    </visual>
    <collision>
      <geometry>
        <mesh filename="package://cassie_model/meshes/BaseRotZ.stl"/>
      </geometry>
    </collision>
  </link>
  <joint name="LeftHipRoll" type="revolute">
    <origin xyz="-0.049 0.135 0.0" rpy="-0.0 1.57079632679 0.0"/>
    <axis xyz="0 0 1"/>
    <parent link="BaseRotZLink"/>
    <child link="LeftHipRollLink"/>
    <limit effort="5.6" lower="-0.3927" upper="0.3927" velocity="12.1475"/>
  </joint>
  <link name="LeftHipRollLink">
    <inertial>
      <origin xyz="-0.0179 0.0001 0.0257"/>
      <mass value="1.82"/>
      <inertia ixx="0.00464" iyy="0.00559" ixy="-2.61000e-06" ixz="-1.53e-06"  iyz="7.03e-07" izz="0.00272"/>
    </inertial>
    <visual>
      <geometry>
        <mesh filename="package://cassie_model/meshes/LeftHipRoll.stl"/>
      </geometry>
      <material name="">
        <color rgba="1.0 0.43137254902 0.117647058824 1"/>
      </material>
    </visual>
    <collision>
      <geometry>
        <mesh filename="package://cassie_model/meshes/LeftHipRoll.stl"/>
      </geometry>
    </collision>
  </link>
  <joint name="LeftHipYaw" type="revolute">
    <origin xyz="0.09 0.0 0.0" rpy="-0.0 -1.57079632679 0.0"/>
    <axis xyz="0 0 1"/>
    <parent link="LeftHipRollLink"/>
    <child link="LeftHipYawLink"/>
    <limit effort="5.6" lower="-0.3927" upper="0.3927" velocity="12.1475"/>
  </joint>
  <link name="LeftHipYawLink">
    <inertial>
      <origin xyz="0 0 0.0557"/>
      <mass value="1.17"/>
      <inertia ixx="0.00644" ixy="-4e-08" ixz="6.25e-07" iyy="0.00608" iyz="-2.46e-07" izz="0.000842"/>
    </inertial>
    <visual>
      <geometry>
        <mesh filename="package://cassie_model/meshes/LeftHipYaw.stl"/>
      </geometry>
      <material name="">
        <color rgba="0.380392156863 0.38431372549 0.396078431373 1"/>
      </material>
    </visual>
    <collision>
      <geometry>
        <mesh filename="package://cassie_model/meshes/LeftHipYaw.stl"/>
      </geometry>
    </collision>
  </link>
  <joint name="LeftHipPitch" type="revolute">
    <origin xyz="0 0 0" rpy="1.57079632679 1.57079632679 0.0"/>
    <axis xyz="0 0 1"/>
    <parent link="LeftHipYawLink"/>
    <child link="LeftHipPitchLink"/>
    <limit effort="8.75" lower="-0.8727" upper="1.3963" velocity="8.5085"/>
  </joint>
  <link name="LeftHipPitchLink">
    <inertial>
      <origin xyz="0.0595 0.0001 -0.0358"/>
      <mass value="5.52"/>
      <inertia ixx="0.018" ixy="0.000284" ixz="-0.0117" iyy="0.0563" iyz="-1.93e-05" izz="0.0498"/>
    </inertial>
    <visual>
      <geometry>
        <mesh filename="package://cassie_model/meshes/LeftHipPitch.stl"/>
      </geometry>
      <material name="">
        <color rgba="1.0 0.43137254902 0.117647058824 1"/>
      </material>
    </visual>
    <collision>
      <geometry>
        <mesh filename="package://cassie_model/meshes/LeftHipPitch.stl"/>
      </geometry>
    </collision>
  </link>
  <joint name="LeftKneePitch" type="revolute">
    <origin xyz="0.12 0.0 0.0045" rpy="0.0 -0.0 0.0"/>
    <axis xyz="0 0 1"/>
    <parent link="LeftHipPitchLink"/>
    <child link="LeftKneePitchLink"/>
    <limit effort="13.5" lower="-2.8623" upper="-0.84" velocity="8.5085"/>
  </joint>
  <link name="LeftKneePitchLink">
    <inertial>
      <origin xyz="0.134702622169249 0.032064243146603 -0.000925029797378"/>
      <mass value="1.678"/>
      <inertia ixx="0.006173" ixy="0.006177" ixz="-0.000677" iyy="0.118852" iyz="0.0000014" izz="0.124292"/>
    </inertial>
    <visual>
      <geometry>
        <mesh filename="package://cassie_model/meshes/LeftKneePitch.stl"/>
      </geometry>
      <material name="">
        <color rgba="0.380392156863 0.38431372549 0.396078431373 1"/>
      </material>
    </visual>
    <collision>
      <geometry>
        <mesh filename="package://cassie_model/meshes/LeftKneePitch.stl"/>
      </geometry>
    </collision>
  </link>
  <joint name="LeftTarsusPitch" type="revolute">
    <origin xyz="0.49544 0.06741 0.0" rpy="0.0 -0.0 0.0"/>
    <axis xyz="0 0 1"/>
    <parent link="LeftKneePitchLink"/>
    <child link="LeftTarsusPitchLink"/>
    <limit effort="400.0" lower="0.75" upper="3" velocity="15.0"/>
  </joint>
  <link name="LeftTarsusPitchLink">
    <inertial>
      <origin xyz="0.09597 -0.03414 0.00327"/>
      <mass value="1.1560"/>
      <inertia ixx="0.00207" ixy="-0.0009585" ixz="0.000078" iyy="0.037055" iyz="0.000152" izz="0.038485"/>
    </inertial>
    <visual>
      <geometry>
        <mesh filename="package://cassie_model/meshes/LeftTarsusPitch.stl"/>
      </geometry>
      <material name="">
        <color rgba="0.380392156863 0.38431372549 0.396078431373 1"/>
      </material>
    </visual>
    <collision>
      <geometry>
        <mesh filename="package://cassie_model/meshes/LeftTarsusPitch.stl"/>
      </geometry>
    </collision>
  </link> 
  <joint name="LeftToePitch" type="revolute">
    <origin xyz="0.408 -0.04 0.0" rpy="0.0 -0.0 0.0"/>
    <axis xyz="0 0 1"/>
    <parent link="LeftTarsusPitchLink"/>
    <child link="LeftToePitchLink"/>
    <limit effort="1.1" lower="-2.4435" upper="-0.5236" velocity="11.5192"/>
  </joint>
  <link name="LeftToePitchLink">
    <inertial>
      <origin xyz="0.0047 0.0275 -0.0001"/>
      <mass value="0.15"/>
      <inertia ixx="0.000287" ixy="-9.86e-05" ixz="-1.46e-06" iyy="0.000171" iyz="1.72e-07" izz="0.000449"/>
    </inertial>
    <visual>
      <geometry>
        <mesh filename="package://cassie_model/meshes/LeftToePitch.stl"/>
      </geometry>
      <material name="">
        <color rgba="1.0 0.43137254902 0.117647058824 1"/>
      </material>
    </visual>
    <collision>
      <geometry>
        <mesh filename="package://cassie_model/meshes/LeftToePitch.stl"/>
      </geometry>
    </collision>
  </link>
  <joint name="RightHipRoll" type="revolute">
    <origin xyz="-0.049 -0.135 0.0" rpy="-0.0 1.57079632679 0.0"/>
    <axis xyz="0 0 1"/>
    <parent link="BaseRotZLink"/>
    <child link="RightHipRollLink"/>
    <limit effort="5.6" lower="-0.3927" upper="0.3927" velocity="12.1475"/>
  </joint>
  <link name="RightHipRollLink">
    <inertial>
      <origin xyz="-0.0179 -0.0001 0.0257"/>
      <mass value="1.82"/>
      <inertia ixx="0.00464" ixy="2.61e-06" ixz="-1.53e-06" iyy="0.00559" iyz="-7.03e-07" izz="0.00272"/>
    </inertial>
    <visual>
      <geometry>
        <mesh filename="package://cassie_model/meshes/RightHipRoll.stl"/>
      </geometry>
      <material name="">
        <color rgba="1.0 0.43137254902 0.117647058824 1"/>
      </material>
    </visual>
    <collision>
      <geometry>
        <mesh filename="package://cassie_model/meshes/RightHipRoll.stl"/>
      </geometry>
    </collision>
  </link>
  <joint name="RightHipYaw" type="revolute">
    <origin xyz="0.09 0.0 0.0" rpy="-0.0 -1.57079632679 0.0"/>
    <axis xyz="0 0 1"/>
    <parent link="RightHipRollLink"/>
    <child link="RightHipYawLink"/>
    <limit effort="5.6" lower="-0.3927" upper="0.3927" velocity="12.1475"/>
  </joint>
  <link name="RightHipYawLink">
    <inertial>
      <origin xyz="0 0 0.0557"/>
      <mass value="1.17"/>
      <inertia ixx="0.00644" ixy="4e-08" ixz="6.25e-07" iyy="0.00608" iyz="2.46e-07" izz="0.000842"/>
    </inertial>
    <visual>
      <geometry>
        <mesh filename="package://cassie_model/meshes/RightHipYaw.stl"/>
      </geometry>
      <material name="">
        <color rgba="0.380392156863 0.38431372549 0.396078431373 1"/>
      </material>
    </visual>
    <collision>
      <geometry>
        <mesh filename="package://cassie_model/meshes/RightHipYaw.stl"/>
      </geometry>
    </collision>
  </link>
  <joint name="RightHipPitch" type="revolute">
    <origin xyz="0 0 0" rpy="1.57079632679 1.57079632679 0.0"/>
    <axis xyz="0 0 1"/>
    <parent link="RightHipYawLink"/>
    <child link="RightHipPitchLink"/>
    <limit effort="8.75" lower="-0.8727" upper="1.3963" velocity="8.5085"/>
  </joint>
  <link name="RightHipPitchLink">
    <inertial>
      <origin xyz="0.0595 0.0001 0.0358"/>
      <mass value="5.52"/>
      <inertia ixx="0.018" ixy="0.000284" ixz="0.0117" iyy="0.0563" iyz="1.93e-05" izz="0.0498"/>
    </inertial>
    <visual>
      <geometry>
        <mesh filename="package://cassie_model/meshes/RightHipPitch.stl"/>
      </geometry>
      <material name="">
        <color rgba="1.0 0.43137254902 0.117647058824 1"/>
      </material>
    </visual>
    <collision>
      <geometry>
        <mesh filename="package://cassie_model/meshes/RightHipPitch.stl"/>
      </geometry>
    </collision>
  </link>
  <joint name="RightKneePitch" type="revolute">
    <origin xyz="0.12 0.0 -0.0045" rpy="0.0 -0.0 0.0"/>
    <axis xyz="0 0 1"/>
    <parent link="RightHipPitchLink"/>
    <child link="RightKneePitchLink"/>
    <limit effort="13.5" lower="-2.8623" upper="-0.84" velocity="8.5085"/>
  </joint>
  <link name="RightKneePitchLink">
    <inertial>
      <origin xyz="0.134702622169249 0.032064243146603 0.000925029797378"/>
      <mass value="1.678"/>
      <inertia ixx="0.006173" ixy="0.006177" ixz="0.000677" iyy="0.118852" iyz="-0.0000014" izz="0.124292"/>
    </inertial>
    <visual>
      <geometry>
        <mesh filename="package://cassie_model/meshes/RightKneePitch.stl"/>
      </geometry>
      <material name="">
        <color rgba="0.380392156863 0.38431372549 0.396078431373 1"/>
      </material>
    </visual>
    <collision>
      <geometry>
        <mesh filename="package://cassie_model/meshes/RightKneePitch.stl"/>
      </geometry>
    </collision>
  </link>
  <joint name="RightTarsusPitch" type="revolute">
    <origin xyz="0.49544 0.06741 0.0" rpy="0.0 -0.0 0.0"/>
    <axis xyz="0 0 1"/>
    <parent link="RightKneePitchLink"/>
    <child link="RightTarsusPitchLink"/>
    <limit effort="400.0" lower="0.75" upper="3" velocity="15.0"/>
  </joint>
  <link name="RightTarsusPitchLink">
    <inertial>
      <origin xyz="0.09597 -0.03414 -0.00327"/>
      <mass value="1.156"/>
      <inertia ixx="0.002070" ixy="-0.0009585" ixz="-0.000078" iyy="0.037055" iyz="-0.000152" izz="0.038485"/>
    </inertial>
    <visual>
      <geometry>
        <mesh filename="package://cassie_model/meshes/RightTarsusPitch.stl"/>
      </geometry>
      <material name="">
        <color rgba="0.380392156863 0.38431372549 0.396078431373 1"/>
      </material>
    </visual>
    <collision>
      <geometry>
        <mesh filename="package://cassie_model/meshes/RightTarsusPitch.stl"/>
      </geometry>
    </collision>
  </link>
  <joint name="RightToePitch" type="revolute">
    <origin xyz="0.408 -0.04 0.0" rpy="0.0 -0.0 0.0"/>
    <axis xyz="0 0 1"/>
    <parent link="RightTarsusPitchLink"/>
    <child link="RightToePitchLink"/>
    <limit effort="1.1" lower="-2.4435" upper="-0.5236" velocity="11.5192"/>
  </joint>
  <link name="RightToePitchLink">
    <inertial>
      <origin xyz="0.0047 0.0275 0.0001"/>
      <mass value="0.15"/>
      <inertia ixx="0.000287" ixy="-9.86e-05" ixz="1.46e-06" iyy="0.000171" iyz="-1.72e-07" izz="0.000449"/>
    </inertial>
    <visual>
      <geometry>
        <mesh filename="package://cassie_model/meshes/RightToePitch.stl"/>
      </geometry>
      <material name="">
        <color rgba="1.0 0.43137254902 0.117647058824 1"/>
      </material>
    </visual>
    <collision>
      <geometry>
        <mesh filename="package://cassie_model/meshes/RightToePitch.stl"/>
      </geometry>
    </collision>
  </link>
  <transmission name="LeftHipRollTransmission">
    <joint name="LeftHipRoll"/>
    <actuator>
      <mechanicalReduction>25</mechanicalReduction>
      <motorInertia>6.62e-05</motorInertia>
    </actuator>
  </transmission>
  <transmission name="LeftHipYawTransmission">
    <joint name="LeftHipYaw"/>
    <actuator>
      <mechanicalReduction>25</mechanicalReduction>
      <motorInertia>6.62e-05</motorInertia>
    </actuator>
  </transmission>
  <transmission name="LeftHipPitchTransmission">
    <joint name="LeftHipPitch"/>
    <actuator>
      <mechanicalReduction>16</mechanicalReduction>
      <motorInertia>0.000365</motorInertia>
    </actuator>
  </transmission>
  <transmission name="LeftKneePitchTransmission">
    <joint name="LeftKneePitch"/>
    <actuator>
      <mechanicalReduction>16</mechanicalReduction>
      <motorInertia>0.000365</motorInertia>
    </actuator>
  </transmission>
  <transmission name="LeftToePitchTransmission">
    <joint name="LeftToePitch"/>
    <actuator>
      <mechanicalReduction>50</mechanicalReduction>
      <motorInertia>4.9e-06</motorInertia>
    </actuator>
  </transmission>
  <transmission name="RightHipRollTransmission">
    <joint name="RightHipRoll"/>
    <actuator>
      <mechanicalReduction>25</mechanicalReduction>
      <motorInertia>6.62e-05</motorInertia>
    </actuator>
  </transmission>
  <transmission name="RightHipYawTransmission">
    <joint name="RightHipYaw"/>
    <actuator>
      <mechanicalReduction>25</mechanicalReduction>
      <motorInertia>6.62e-05</motorInertia>
    </actuator>
  </transmission>
  <transmission name="RightHipPitchTransmission">
    <joint name="RightHipPitch"/>
    <actuator>
      <mechanicalReduction>16</mechanicalReduction>
      <motorInertia>0.000365</motorInertia>
    </actuator>
  </transmission>
  <transmission name="RightKneePitchTransmission">
    <joint name="RightKneePitch"/>
    <actuator>
      <mechanicalReduction>16</mechanicalReduction>
      <motorInertia>0.000365</motorInertia>
    </actuator>
  </transmission>
  <transmission name="RightToePitchTransmission">
    <joint name="RightToePitch"/>
    <actuator>
      <mechanicalReduction>50</mechanicalReduction>
      <motorInertia>4.9e-06</motorInertia>
    </actuator>
  </transmission>
</robot>
