<?xml version="1.0" ?>
<!-- =================================================================================== -->
<!-- |    This document was autogenerated by xacro from cassie_simple.xacro            | -->
<!-- |    EDITING THIS FILE BY HAND IS NOT RECOMMENDED                                 | -->
<!-- =================================================================================== -->
<!-- Author: Xiaobin Xiong
     Date:   5/02/2022  
     Changed inertial to mujoco model
      -->
<robot name="cassie_model" xmlns:xacro="http://ros.org/wiki/xacro">
  <link name="BaseRotZLink">
    <inertial>
      <origin xyz="0.05066 0.000346 0.02841"/>
      <mass value="10.33"/>
      <inertia ixx="8.582100e-02" iyy="4.922200e-02" izz="8.626000e-02" ixy="1.276000e-05" ixz="-1.602200e-04" iyz="-4.140000e-04"/> 
    </inertial>
    <visual>
      <geometry>
        <mesh filename="package://cassie_model/meshes/BaseRotZ.stl"/>
      </geometry>
      <material name="">
        <color rgba="1.0 0.43137254902 0.117647058824 1"/>
      </material>
    </visual>
    <collision>
      <geometry>
        <mesh filename="package://cassie_model/meshes/BaseRotZ.stl"/>
      </geometry>
    </collision>
  </link>
  <joint name="LeftHipRoll" type="revolute">
    <origin xyz="0.021 0.135 0" rpy="-0.0 1.57079632679 0.0"/>
    <axis xyz="0 0 1"/>
    <parent link="BaseRotZLink"/>
    <child link="LeftHipRollLink"/>
    <limit effort="5.6" lower="-0.3927" upper="0.3927" velocity="12.1475"/>
  </joint>
  <link name="LeftHipRollLink">
    <inertial>
      <origin xyz="-0.01793 0.0001 -0.04428"/>
      <mass value="1.82"/>
      <inertia ixx="3.431000e-03" iyy="3.793000e-03" izz="2.135000e-03" ixy="-6.650000e-07" ixz="-8.400000e-04" iyz="3.990000e-06"/> 
    </inertial>
    <visual>
      <geometry>
        <mesh filename="package://cassie_model/meshes/LeftHipRoll.stl"/>
      </geometry>
      <material name="">
        <color rgba="1.0 0.43137254902 0.117647058824 1"/>
      </material>
    </visual>
    <collision>
      <geometry>
        <mesh filename="package://cassie_model/meshes/LeftHipRoll.stl"/>
      </geometry>
    </collision>
  </link>
  <joint name="LeftHipYaw" type="revolute">
    <origin xyz="0 0 -0.07" rpy="-0.0 -1.57079632679 0.0"/>
    <axis xyz="0 0 1"/>
    <parent link="LeftHipRollLink"/>
    <child link="LeftHipYawLink"/>
    <limit effort="5.6" lower="-0.3927" upper="0.3927" velocity="12.1475"/>
  </joint>
  <link name="LeftHipYawLink">
    <inertial>
      <origin xyz="0 -1e-05 -0.034277"/>
      <mass value="1.171"/>
      <inertia ixx="2.443000e-03" iyy="2.803000e-03" izz="8.420000e-04" ixy="-4.000000e-08" ixz="2.462000e-07" iyz="-2.710000e-08"/> 
    </inertial>
    <visual>
      <geometry>
        <mesh filename="package://cassie_model/meshes/LeftHipYaw.stl"/>
      </geometry>
      <material name="">
        <color rgba="0.380392156863 0.38431372549 0.396078431373 1"/>
      </material>
    </visual>
    <collision>
      <geometry>
        <mesh filename="package://cassie_model/meshes/LeftHipYaw.stl"/>
      </geometry>
    </collision>
  </link>
  <joint name="LeftHipPitch" type="revolute">
    <origin xyz="0 0 -0.09" rpy="1.57079632679 1.57079632679 0.0"/>
    <axis xyz="0 0 1"/>
    <parent link="LeftHipYawLink"/>
    <child link="LeftHipPitchLink"/>
    <limit effort="8.75" lower="-0.8727" upper="1.3963" velocity="8.5085"/>
  </joint>
  <link name="LeftHipPitchLink">
    <inertial>
      <origin xyz="0.05946 5e-05 -0.03581"/>
      <mass value="5.52"/>
      <inertia ixx="1.089800e-02" iyy="2.971400e-02" izz="3.025700e-02" ixy="-2.669000e-04" ixz="-5.721000e-05" iyz="9.170000e-06"/> 
    </inertial>
    <visual>
      <geometry>
        <mesh filename="package://cassie_model/meshes/LeftHipPitch.stl"/>
      </geometry>
      <material name="">
        <color rgba="1.0 0.43137254902 0.117647058824 1"/>
      </material>
    </visual>
    <collision>
      <geometry>
        <mesh filename="package://cassie_model/meshes/LeftHipPitch.stl"/>
      </geometry>
    </collision>
  </link>
  <joint name="LeftKneePitch" type="revolute">
    <origin xyz="0.12 0.0 0.0045" rpy="0.0 -0.0 0.0"/>
    <axis xyz="0 0 1"/>
    <parent link="LeftHipPitchLink"/>
    <child link="LeftKneePitchLink"/>
    <limit effort="13.5" lower="-2.8623" upper="-0.84" velocity="8.5085"/>
  </joint>
  <link name="LeftKneePitchLink">
    <inertial>
      <origin xyz=" 0.122528 0.037958 -0.002087"/> 
      <mass value="2.0715"/> 
      <inertia ixx="5.991095e-03" iyy="3.546864e-02" izz="4.393283e-02" ixy="-1.127159e-03" ixz="9.942444e-05" iyz="-5.408263e-04"/>  
    </inertial>
    <visual>
      <geometry>
        <mesh filename="package://cassie_model/meshes/LeftKneePitch.stl"/>
      </geometry>
      <material name="">
        <color rgba="0.380392156863 0.38431372549 0.396078431373 1"/>
      </material>
    </visual>
    <collision>
      <geometry>
        <mesh filename="package://cassie_model/meshes/LeftKneePitch.stl"/>
      </geometry>
    </collision>
  </link>
  <joint name="LeftTarsusPitch" type="revolute">
    <origin xyz="0.49544 0.06741 0.0"/>
    <axis xyz="0 0 1"/>
    <parent link="LeftKneePitchLink"/>
    <child link="LeftTarsusPitchLink"/>
    <limit effort="400.0" lower="0.75" upper="3" velocity="15.0"/>
  </joint>
  <link name="LeftTarsusPitchLink">
    <inertial>
      <origin xyz=" 0.052430 -0.020460 0.003423"/> 
      <mass value="1.5627"/> 
      <inertia ixx="7.990194e-04" iyy="3.613873e-02" izz="3.660963e-02" ixy="3.096415e-03" ixz="-1.208586e-04" iyz="-2.569149e-08"/> 
    </inertial>
    <visual>
      <geometry>
        <mesh filename="package://cassie_model/meshes/LeftTarsusPitch.stl"/>
      </geometry>
      <material name="">
        <color rgba="0.380392156863 0.38431372549 0.396078431373 1"/>
      </material>
    </visual>
    <collision>
      <geometry>
        <mesh filename="package://cassie_model/meshes/LeftTarsusPitch.stl"/>
      </geometry>
    </collision>
  </link> 
  <joint name="LeftToePitch" type="revolute">
    <origin xyz="0.408 -0.04 0.0" />
    <axis xyz="0 0 1"/>
    <parent link="LeftTarsusPitchLink"/>
    <child link="LeftToePitchLink"/>
    <limit effort="1.1" lower="-2.4435" upper="-0.5236" velocity="11.5192"/>
  </joint>
  <link name="LeftToePitchLink">
    <inertial>
      <origin xyz="0.00474 0.02748 -0.00014"/>
      <mass value="0.1498"/>
      <inertia ixx="1.738800e-04" iyy="1.679300e-04" izz="3.326100e-04" ixy="1.181400e-04" ixz="1.360000e-06" iyz="-4.000000e-07"/> 
    </inertial>
    <visual>
      <geometry>
        <mesh filename="package://cassie_model/meshes/LeftToePitch.stl"/>
      </geometry>
      <material name="">
        <color rgba="1.0 0.43137254902 0.117647058824 1"/>
      </material>
    </visual>
    <collision>
      <geometry>
        <mesh filename="package://cassie_model/meshes/LeftToePitch.stl"/>
      </geometry>
    </collision>
  </link>
  <joint name="RightHipRoll" type="revolute">
    <origin xyz="0.021 -0.135 0" rpy="-0.0 1.57079632679 0.0"/>
    <axis xyz="0 0 1"/>
    <parent link="BaseRotZLink"/>
    <child link="RightHipRollLink"/>
    <limit effort="5.6" lower="-0.3927" upper="0.3927" velocity="12.1475"/>
  </joint>
  <link name="RightHipRollLink">
    <inertial>
      <origin xyz="-0.01793 0.0001 -0.04428"/>
      <mass value="1.82"/>
      <inertia ixx="3.431000e-03" iyy="3.793000e-03" izz="2.135000e-03" ixy="6.650000e-07" ixz="-8.400000e-04" iyz="-3.990000e-06"/> 
    </inertial>
    <visual>
      <geometry>
        <mesh filename="package://cassie_model/meshes/RightHipRoll.stl"/>
      </geometry>
      <material name="">
        <color rgba="1.0 0.43137254902 0.117647058824 1"/>
      </material>
    </visual>
    <collision>
      <geometry>
        <mesh filename="package://cassie_model/meshes/RightHipRoll.stl"/>
      </geometry>
    </collision>
  </link>
  <joint name="RightHipYaw" type="revolute">
    <origin xyz="0 0 -0.07" rpy="-0.0 -1.57079632679 0.0"/>
    <axis xyz="0 0 1"/>
    <parent link="RightHipRollLink"/>
    <child link="RightHipYawLink"/>
    <limit effort="5.6" lower="-0.3927" upper="0.3927" velocity="12.1475"/>
  </joint>
  <link name="RightHipYawLink">
    <inertial>
      <origin xyz="0 1e-05 -0.034277"/>
      <mass value="1.171"/>
      <inertia ixx="2.443000e-03" iyy="2.803000e-03" izz="8.420000e-04" ixy="4.000000e-08" ixz="2.462000e-07" iyz="2.710000e-08"/> 
    </inertial>
    <visual>
      <geometry>
        <mesh filename="package://cassie_model/meshes/RightHipYaw.stl"/>
      </geometry>
      <material name="">
        <color rgba="0.380392156863 0.38431372549 0.396078431373 1"/>
      </material>
    </visual>
    <collision>
      <geometry>
        <mesh filename="package://cassie_model/meshes/RightHipYaw.stl"/>
      </geometry>
    </collision>
  </link>
  <joint name="RightHipPitch" type="revolute">
    <origin xyz="0 0 -0.09" rpy="1.57079632679 1.57079632679 0.0"/>
    <axis xyz="0 0 1"/>
    <parent link="RightHipYawLink"/>
    <child link="RightHipPitchLink"/>
    <limit effort="8.75" lower="-0.8727" upper="1.3963" velocity="8.5085"/>
  </joint>
  <link name="RightHipPitchLink">
    <inertial>
      <origin xyz="0.05946 5e-05 0.03581"/>
      <mass value="5.52"/>
      <inertia ixx="1.089800e-02" iyy="2.971400e-02" izz="3.025700e-02" ixy="-2.669000e-04" ixz="5.721000e-05" iyz="-9.170000e-06"/> 
    </inertial>
    <visual>
      <geometry>
        <mesh filename="package://cassie_model/meshes/RightHipPitch.stl"/>
      </geometry>
      <material name="">
        <color rgba="1.0 0.43137254902 0.117647058824 1"/>
      </material>
    </visual>
    <collision>
      <geometry>
        <mesh filename="package://cassie_model/meshes/RightHipPitch.stl"/>
      </geometry>
    </collision>
  </link>
  <joint name="RightKneePitch" type="revolute">
    <origin xyz="0.12 0.0 -0.0045"/>
    <axis xyz="0 0 1"/>
    <parent link="RightHipPitchLink"/>
    <child link="RightKneePitchLink"/>
    <limit effort="13.5" lower="-2.8623" upper="-0.84" velocity="8.5085"/>
  </joint>
  <link name="RightKneePitchLink">
    <inertial>
      <origin xyz=" 0.122528 0.037958 0.002087"/> 
      <mass value="2.0715"/> 
      <inertia ixx="7.217775e-03" iyy="3.657381e-02" izz="4.605433e-02" ixy="-1.619044e-03" ixz="-7.733864e-05" iyz="5.894120e-04"/> 
    </inertial>
    <visual>
      <geometry>
        <mesh filename="package://cassie_model/meshes/RightKneePitch.stl"/>
      </geometry>
      <material name="">
        <color rgba="0.380392156863 0.38431372549 0.396078431373 1"/>
      </material>
    </visual>
    <collision>
      <geometry>
        <mesh filename="package://cassie_model/meshes/RightKneePitch.stl"/>
      </geometry>
    </collision>
  </link>
  <joint name="RightTarsusPitch" type="revolute">
    <origin xyz="0.49544 0.06741 0.0"/>
    <axis xyz="0 0 1"/>
    <parent link="RightKneePitchLink"/>
    <child link="RightTarsusPitchLink"/>
    <limit effort="400.0" lower="0.75" upper="3" velocity="15.0"/>
  </joint>
  <link name="RightTarsusPitchLink">
    <inertial>
      <origin xyz=" 0.052430 -0.020460 -0.003423"/> 
      <mass value="1.5627"/> 
      <inertia ixx="7.990194e-04" iyy="3.613873e-02" izz="3.660963e-02" ixy="3.096415e-03" ixz="1.208586e-04" iyz="2.569149e-08"/> 
    </inertial>
    <visual>
      <geometry>
        <mesh filename="package://cassie_model/meshes/RightTarsusPitch.stl"/>
      </geometry>
      <material name="">
        <color rgba="0.380392156863 0.38431372549 0.396078431373 1"/>
      </material>
    </visual>
    <collision>
      <geometry>
        <mesh filename="package://cassie_model/meshes/RightTarsusPitch.stl"/>
      </geometry>
    </collision>
  </link> 
  <joint name="RightToePitch" type="revolute">
    <origin xyz="0.408 -0.04 0.0" />
    <axis xyz="0 0 1"/>
    <parent link="RightTarsusPitchLink"/>
    <child link="RightToePitchLink"/>
    <limit effort="1.1" lower="-2.4435" upper="-0.5236" velocity="11.5192"/>
  </joint>
  <link name="RightToePitchLink">
    <inertial>
      <origin xyz="0.00474 0.02748 0.00014"/>
      <mass value="0.1498"/>
      <inertia ixx="1.738800e-04" iyy="1.679300e-04" izz="3.326100e-04" ixy="1.181400e-04" ixz="-1.360000e-06" iyz="4.000000e-07"/> 
    </inertial>
    <visual>
      <geometry>
        <mesh filename="package://cassie_model/meshes/RightToePitch.stl"/>
      </geometry>
      <material name="">
        <color rgba="1.0 0.43137254902 0.117647058824 1"/>
      </material>
    </visual>
    <collision>
      <geometry>
        <mesh filename="package://cassie_model/meshes/RightToePitch.stl"/>
      </geometry>
    </collision>
  </link>
  <transmission name="LeftHipRollTransmission">
    <joint name="LeftHipRoll"/>
    <actuator>
      <mechanicalReduction>25</mechanicalReduction>
      <motorInertia>6.62e-05</motorInertia>
    </actuator>
  </transmission>
  <transmission name="LeftHipYawTransmission">
    <joint name="LeftHipYaw"/>
    <actuator>
      <mechanicalReduction>25</mechanicalReduction>
      <motorInertia>6.62e-05</motorInertia>
    </actuator>
  </transmission>
  <transmission name="LeftHipPitchTransmission">
    <joint name="LeftHipPitch"/>
    <actuator>
      <mechanicalReduction>16</mechanicalReduction>
      <motorInertia>0.000365</motorInertia>
    </actuator>
  </transmission>
  <transmission name="LeftKneePitchTransmission">
    <joint name="LeftKneePitch"/>
    <actuator>
      <mechanicalReduction>16</mechanicalReduction>
      <motorInertia>0.000365</motorInertia>
    </actuator>
  </transmission>
  <transmission name="LeftToePitchTransmission">
    <joint name="LeftToePitch"/>
    <actuator>
      <mechanicalReduction>50</mechanicalReduction>
      <motorInertia>4.9e-06</motorInertia>
    </actuator>
  </transmission>
  <transmission name="RightHipRollTransmission">
    <joint name="RightHipRoll"/>
    <actuator>
      <mechanicalReduction>25</mechanicalReduction>
      <motorInertia>6.62e-05</motorInertia>
    </actuator>
  </transmission>
  <transmission name="RightHipYawTransmission">
    <joint name="RightHipYaw"/>
    <actuator>
      <mechanicalReduction>25</mechanicalReduction>
      <motorInertia>6.62e-05</motorInertia>
    </actuator>
  </transmission>
  <transmission name="RightHipPitchTransmission">
    <joint name="RightHipPitch"/>
    <actuator>
      <mechanicalReduction>16</mechanicalReduction>
      <motorInertia>0.000365</motorInertia>
    </actuator>
  </transmission>
  <transmission name="RightKneePitchTransmission">
    <joint name="RightKneePitch"/>
    <actuator>
      <mechanicalReduction>16</mechanicalReduction>
      <motorInertia>0.000365</motorInertia>
    </actuator>
  </transmission>
  <transmission name="RightToePitchTransmission">
    <joint name="RightToePitch"/>
    <actuator>
      <mechanicalReduction>50</mechanicalReduction>
      <motorInertia>4.9e-06</motorInertia>
    </actuator>
  </transmission>
</robot>
