<?xml version="1.0" encoding="UTF-8"?>
<robot name="cassie_model">
    <link name="BaseRotZLink">
        <inertial>
            <origin xyz="0.05066 0.000346 0.02841"/>
            <mass value="10.33"/>
            <inertia ixx="0.085821" iyy="0.049222" izz="0.08626" ixy="1.276e-05" ixz="-0.00016022" iyz="-0.000414"/>
        </inertial>
        <visual>
            <geometry>
                <mesh filename="package://cassie_model/meshes/BaseRotZ.stl"/>
            </geometry>
            <material name="">
                <color rgba="1.0 0.43137254902 0.117647058824 1"/>
            </material>
        </visual>
        <collision>
            <geometry>
                <mesh filename="package://cassie_model/meshes/BaseRotZ.stl"/>
            </geometry>
        </collision>
    </link>
    <link name="LeftHipRollLink">
        <inertial>
            <origin xyz="-0.01793 0.0001 -0.04428"/>
            <mass value="1.82"/>
            <inertia ixx="0.003431" iyy="0.003793" izz="0.002135" ixy="-6.65e-07" ixz="-0.00084" iyz="3.99e-06"/>
        </inertial>
        <visual>
            <geometry>
                <mesh filename="package://cassie_model/meshes/LeftHipRoll.stl"/>
            </geometry>
            <material name="">
                <color rgba="1.0 0.43137254902 0.117647058824 1"/>
            </material>
        </visual>
        <collision>
            <geometry>
                <mesh filename="package://cassie_model/meshes/LeftHipRoll.stl"/>
            </geometry>
        </collision>
    </link>
    <link name="LeftHipYawLink">
        <inertial>
            <origin xyz="0 -1e-05 -0.034277"/>
            <mass value="1.171"/>
            <inertia ixx="0.002443" iyy="0.002803" izz="0.000842" ixy="-4e-08" ixz="2.462e-07" iyz="-2.71e-08"/>
        </inertial>
        <visual>
            <geometry>
                <mesh filename="package://cassie_model/meshes/LeftHipYaw.stl"/>
            </geometry>
            <material name="">
                <color rgba="0.380392156863 0.38431372549 0.396078431373 1"/>
            </material>
        </visual>
        <collision>
            <geometry>
                <mesh filename="package://cassie_model/meshes/LeftHipYaw.stl"/>
            </geometry>
        </collision>
    </link>
    <link name="LeftHipPitchLink">
        <inertial>
            <origin xyz="0.05946 5e-05 -0.03581"/>
            <mass value="5.52"/>
            <inertia ixx="0.010898" iyy="0.029714" izz="0.030257" ixy="-0.0002669" ixz="-5.721e-05" iyz="9.17e-06"/>
        </inertial>
        <visual>
            <geometry>
                <mesh filename="package://cassie_model/meshes/LeftHipPitch.stl"/>
            </geometry>
            <material name="">
                <color rgba="1.0 0.43137254902 0.117647058824 1"/>
            </material>
        </visual>
        <collision>
            <geometry>
                <mesh filename="package://cassie_model/meshes/LeftHipPitch.stl"/>
            </geometry>
        </collision>
    </link>
    <link name="LeftKneePitchLink">
        <inertial>
            <origin xyz="0.117419 0.026719 -0.002577"/>
            <mass value="5.0325"/>
            <inertia ixx="0.017973" iyy="0.10641" izz="0.1318" ixy="-0.0033815" ixz="0.00029827" iyz="-0.0016225"/>
        </inertial>
        <visual>
            <geometry>
                <mesh filename="package://cassie_model/meshes/LeftKneePitch.stl"/>
            </geometry>
            <material name="">
                <color rgba="0.380392156863 0.38431372549 0.396078431373 1"/>
            </material>
        </visual>
        <collision>
            <geometry>
                <mesh filename="package://cassie_model/meshes/LeftKneePitch.stl"/>
            </geometry>
        </collision>
    </link>
    <link name="LeftTarsusPitchLink">
        <inertial>
            <origin xyz="0.102192 -0.027909 0.003303"/>
            <mass value="3.4581"/>
            <inertia ixx="0.0017878" iyy="0.074021" izz="0.074502" ixy="0.0034183" ixz="-0.00052983" iyz="1.5311e-05"/>
        </inertial>
        <visual>
            <geometry>
                <mesh filename="package://cassie_model/meshes/LeftTarsusPitch.stl"/>
            </geometry>
            <material name="">
                <color rgba="0.380392156863 0.38431372549 0.396078431373 1"/>
            </material>
        </visual>
        <collision>
            <geometry>
                <mesh filename="package://cassie_model/meshes/LeftTarsusPitch.stl"/>
            </geometry>
        </collision>
    </link>
    <link name="LeftToePitchLink">
        <inertial>
            <origin xyz="0.00474 0.02748 -0.00014"/>
            <mass value="0.4494"/>
            <inertia ixx="0.00052164" iyy="0.00050379" izz="0.00099783" ixy="0.00035442" ixz="4.08e-06" iyz="-1.2e-06"/>
        </inertial>
        <visual>
            <geometry>
                <mesh filename="package://cassie_model/meshes/LeftToePitch.stl"/>
            </geometry>
            <material name="">
                <color rgba="1.0 0.43137254902 0.117647058824 1"/>
            </material>
        </visual>
        <collision>
            <geometry>
                <mesh filename="package://cassie_model/meshes/LeftToePitch.stl"/>
            </geometry>
        </collision>
    </link>
    <link name="RightHipRollLink">
        <inertial>
            <origin xyz="-0.01793 0.0001 -0.04428"/>
            <mass value="1.82"/>
            <inertia ixx="0.003431" iyy="0.003793" izz="0.002135" ixy="6.65e-07" ixz="-0.00084" iyz="-3.99e-06"/>
        </inertial>
        <visual>
            <geometry>
                <mesh filename="package://cassie_model/meshes/RightHipRoll.stl"/>
            </geometry>
            <material name="">
                <color rgba="1.0 0.43137254902 0.117647058824 1"/>
            </material>
        </visual>
        <collision>
            <geometry>
                <mesh filename="package://cassie_model/meshes/RightHipRoll.stl"/>
            </geometry>
        </collision>
    </link>
    <link name="RightHipYawLink">
        <inertial>
            <origin xyz="0 1e-05 -0.034277"/>
            <mass value="1.171"/>
            <inertia ixx="0.002443" iyy="0.002803" izz="0.000842" ixy="4e-08" ixz="2.462e-07" iyz="2.71e-08"/>
        </inertial>
        <visual>
            <geometry>
                <mesh filename="package://cassie_model/meshes/RightHipYaw.stl"/>
            </geometry>
            <material name="">
                <color rgba="0.380392156863 0.38431372549 0.396078431373 1"/>
            </material>
        </visual>
        <collision>
            <geometry>
                <mesh filename="package://cassie_model/meshes/RightHipYaw.stl"/>
            </geometry>
        </collision>
    </link>
    <link name="RightHipPitchLink">
        <inertial>
            <origin xyz="0.05946 5e-05 0.03581"/>
            <mass value="5.52"/>
            <inertia ixx="0.010898" iyy="0.029714" izz="0.030257" ixy="-0.0002669" ixz="5.721e-05" iyz="-9.17e-06"/>
        </inertial>
        <visual>
            <geometry>
                <mesh filename="package://cassie_model/meshes/RightHipPitch.stl"/>
            </geometry>
            <material name="">
                <color rgba="1.0 0.43137254902 0.117647058824 1"/>
            </material>
        </visual>
        <collision>
            <geometry>
                <mesh filename="package://cassie_model/meshes/RightHipPitch.stl"/>
            </geometry>
        </collision>
    </link>
    <link name="RightKneePitchLink">
        <inertial>
            <origin xyz="0.117419 0.026719 0.002577"/>
            <mass value="5.0325"/>
            <inertia ixx="0.017973" iyy="0.10641" izz="0.1318" ixy="-0.0033815" ixz="-0.00029827" iyz="0.0016225"/>
        </inertial>
        <visual>
            <geometry>
                <mesh filename="package://cassie_model/meshes/RightKneePitch.stl"/>
            </geometry>
            <material name="">
                <color rgba="0.380392156863 0.38431372549 0.396078431373 1"/>
            </material>
        </visual>
        <collision>
            <geometry>
                <mesh filename="package://cassie_model/meshes/RightKneePitch.stl"/>
            </geometry>
        </collision>
    </link>
    <link name="RightTarsusPitchLink">
        <inertial>
            <origin xyz="0.102192 -0.027909 -0.003303"/>
            <mass value="3.4581"/>
            <inertia ixx="0.0017878" iyy="0.074021" izz="0.074502" ixy="0.0034183" ixz="0.00052983" iyz="-1.5311e-05"/>
        </inertial>
        <visual>
            <geometry>
                <mesh filename="package://cassie_model/meshes/RightTarsusPitch.stl"/>
            </geometry>
            <material name="">
                <color rgba="0.380392156863 0.38431372549 0.396078431373 1"/>
            </material>
        </visual>
        <collision>
            <geometry>
                <mesh filename="package://cassie_model/meshes/RightTarsusPitch.stl"/>
            </geometry>
        </collision>
    </link>
    <link name="RightToePitchLink">
        <inertial>
            <origin xyz="0.00474 0.02748 0.00014"/>
            <mass value="0.4494"/>
            <inertia ixx="0.00052164" iyy="0.00050379" izz="0.00099783" ixy="0.00035442" ixz="-4.08e-06" iyz="1.2e-06"/>
        </inertial>
        <visual>
            <geometry>
                <mesh filename="package://cassie_model/meshes/RightToePitch.stl"/>
            </geometry>
            <material name="">
                <color rgba="1.0 0.43137254902 0.117647058824 1"/>
            </material>
        </visual>
        <collision>
            <geometry>
                <mesh filename="package://cassie_model/meshes/RightToePitch.stl"/>
            </geometry>
        </collision>
    </link>
    <joint name="LeftHipRoll" type="revolute">
        <origin xyz="0.021 0.135 0" rpy="-0.0 1.57079632679 0.0"/>
        <axis xyz="0 0 1"/>
        <parent link="BaseRotZLink"/>
        <child link="LeftHipRollLink"/>
        <limit effort="5.6" lower="-0.3927" upper="0.3927" velocity="12.1475"/>
    </joint>
    <joint name="LeftHipYaw" type="revolute">
        <origin xyz="0 0 -0.07" rpy="-0.0 -1.57079632679 0.0"/>
        <axis xyz="0 0 1"/>
        <parent link="LeftHipRollLink"/>
        <child link="LeftHipYawLink"/>
        <limit effort="5.6" lower="-0.3927" upper="0.3927" velocity="12.1475"/>
    </joint>
    <joint name="LeftHipPitch" type="revolute">
        <origin xyz="0 0 -0.09" rpy="1.57079632679 1.57079632679 0.0"/>
        <axis xyz="0 0 1"/>
        <parent link="LeftHipYawLink"/>
        <child link="LeftHipPitchLink"/>
        <limit effort="8.75" lower="-0.8727" upper="1.3963" velocity="8.5085"/>
    </joint>
    <joint name="LeftKneePitch" type="revolute">
        <origin xyz="0.12 0.0 0.0045" rpy="0.0 -0.0 0.0"/>
        <axis xyz="0 0 1"/>
        <parent link="LeftHipPitchLink"/>
        <child link="LeftKneePitchLink"/>
        <limit effort="13.5" lower="-2.8623" upper="-0.84" velocity="8.5085"/>
    </joint>
    <joint name="LeftTarsusPitch" type="revolute">
        <origin xyz="0.49544 0.06741 0.0"/>
        <axis xyz="0 0 1"/>
        <parent link="LeftKneePitchLink"/>
        <child link="LeftTarsusPitchLink"/>
        <limit effort="400" lower="0.75" upper="3" velocity="15"/>
    </joint>
    <joint name="LeftToePitch" type="revolute">
        <origin xyz="0.408 -0.04 0.0"/>
        <axis xyz="0 0 1"/>
        <parent link="LeftTarsusPitchLink"/>
        <child link="LeftToePitchLink"/>
        <limit effort="1.1" lower="-2.4435" upper="-0.5236" velocity="11.5192"/>
    </joint>
    <joint name="RightHipRoll" type="revolute">
        <origin xyz="0.021 -0.135 0" rpy="-0.0 1.57079632679 0.0"/>
        <axis xyz="0 0 1"/>
        <parent link="BaseRotZLink"/>
        <child link="RightHipRollLink"/>
        <limit effort="5.6" lower="-0.3927" upper="0.3927" velocity="12.1475"/>
    </joint>
    <joint name="RightHipYaw" type="revolute">
        <origin xyz="0 0 -0.07" rpy="-0.0 -1.57079632679 0.0"/>
        <axis xyz="0 0 1"/>
        <parent link="RightHipRollLink"/>
        <child link="RightHipYawLink"/>
        <limit effort="5.6" lower="-0.3927" upper="0.3927" velocity="12.1475"/>
    </joint>
    <joint name="RightHipPitch" type="revolute">
        <origin xyz="0 0 -0.09" rpy="1.57079632679 1.57079632679 0.0"/>
        <axis xyz="0 0 1"/>
        <parent link="RightHipYawLink"/>
        <child link="RightHipPitchLink"/>
        <limit effort="8.75" lower="-0.8727" upper="1.3963" velocity="8.5085"/>
    </joint>
    <joint name="RightKneePitch" type="revolute">
        <origin xyz="0.12 0.0 -0.0045"/>
        <axis xyz="0 0 1"/>
        <parent link="RightHipPitchLink"/>
        <child link="RightKneePitchLink"/>
        <limit effort="13.5" lower="-2.8623" upper="-0.84" velocity="8.5085"/>
    </joint>
    <joint name="RightTarsusPitch" type="revolute">
        <origin xyz="0.49544 0.06741 0.0"/>
        <axis xyz="0 0 1"/>
        <parent link="RightKneePitchLink"/>
        <child link="RightTarsusPitchLink"/>
        <limit effort="400" lower="0.75" upper="3" velocity="15"/>
    </joint>
    <joint name="RightToePitch" type="revolute">
        <origin xyz="0.408 -0.04 0.0"/>
        <axis xyz="0 0 1"/>
        <parent link="RightTarsusPitchLink"/>
        <child link="RightToePitchLink"/>
        <limit effort="1.1" lower="-2.4435" upper="-0.5236" velocity="11.5192"/>
    </joint>
    <transmission name="LeftHipRollTransmission">
        <joint name="LeftHipRoll"/>
        <actuator>
            <mechanicalReduction>25</mechanicalReduction>
            <motorInertia>6.62e-05</motorInertia>
        </actuator>
    </transmission>
    <transmission name="LeftHipYawTransmission">
        <joint name="LeftHipYaw"/>
        <actuator>
            <mechanicalReduction>25</mechanicalReduction>
            <motorInertia>6.62e-05</motorInertia>
        </actuator>
    </transmission>
    <transmission name="LeftHipPitchTransmission">
        <joint name="LeftHipPitch"/>
        <actuator>
            <mechanicalReduction>16</mechanicalReduction>
            <motorInertia>0.000365</motorInertia>
        </actuator>
    </transmission>
    <transmission name="LeftKneePitchTransmission">
        <joint name="LeftKneePitch"/>
        <actuator>
            <mechanicalReduction>16</mechanicalReduction>
            <motorInertia>0.000365</motorInertia>
        </actuator>
    </transmission>
    <transmission name="LeftToePitchTransmission">
        <joint name="LeftToePitch"/>
        <actuator>
            <mechanicalReduction>50</mechanicalReduction>
            <motorInertia>4.9e-06</motorInertia>
        </actuator>
    </transmission>
    <transmission name="RightHipRollTransmission">
        <joint name="RightHipRoll"/>
        <actuator>
            <mechanicalReduction>25</mechanicalReduction>
            <motorInertia>6.62e-05</motorInertia>
        </actuator>
    </transmission>
    <transmission name="RightHipYawTransmission">
        <joint name="RightHipYaw"/>
        <actuator>
            <mechanicalReduction>25</mechanicalReduction>
            <motorInertia>6.62e-05</motorInertia>
        </actuator>
    </transmission>
    <transmission name="RightHipPitchTransmission">
        <joint name="RightHipPitch"/>
        <actuator>
            <mechanicalReduction>16</mechanicalReduction>
            <motorInertia>0.000365</motorInertia>
        </actuator>
    </transmission>
    <transmission name="RightKneePitchTransmission">
        <joint name="RightKneePitch"/>
        <actuator>
            <mechanicalReduction>16</mechanicalReduction>
            <motorInertia>0.000365</motorInertia>
        </actuator>
    </transmission>
    <transmission name="RightToePitchTransmission">
        <joint name="RightToePitch"/>
        <actuator>
            <mechanicalReduction>50</mechanicalReduction>
            <motorInertia>4.9e-06</motorInertia>
        </actuator>
    </transmission>
</robot>
